File: demodata_MT.csv
Time,Comment,Field (Oe),Temperature (K),Long Moment (emu),Long Scan Std Dev,Long Algorithm,Long Reg Fit,Long Percent Error (%),Trans Moment (emu),Trans Scan Std Dev,Trans Algorithm,Trans Reg Fit,Trans Percent Error (%),Long Moment [w/o ABS] (emu),Long Scan Std Dev [w/o ABS],Long Reg Fit [w/o ABS],Long Percent Error [w/o ABS] (%),Trans Moment [w/o ABS] (emu),Trans Scan Std Dev [w/o ABS],Trans Reg Fit [w/o ABS],Trans Percent Error [w/o ABS] (%),Points per Scan,Scans per Measurement,Scan Length (cm),Delta Temp (K),Rot Position (deg),Error,EC Comp. Running,Using ABS,Unnamed: 30
1627020994.602,,50000.0,9.995996,0.06709214,0.0,3,0.997434,0.0,,,,,,,,,,,,,,32,1,4.0,0.00299263,0.0,0,1,0,
1627021130.701,,50000.0,11.14986,0.06708266,0.0,3,0.9975784,0.0,,,,,,,,,,,,,,32,1,4.0,0.2936602,0.0,0,1,0,
1627021232.291,,50000.0,12.18059,0.06707998,0.0,3,0.9973773,0.0,,,,,,,,,,,,,,32,1,4.0,0.3344002,0.0,0,1,0,
1627021322.408,,50000.0,13.19282,0.06705218,0.0,3,0.9974006,0.0,,,,,,,,,,,,,,32,1,4.0,0.3529406,0.0,0,1,0,
1627021411.931,,50000.0,14.19517,0.06703436,0.0,3,0.997569,0.0,,,,,,,,,,,,,,32,1,4.0,0.3595495,0.0,0,0,0,
1627021504.102,,50000.0,15.2151,0.06701422,0.0,3,0.9974443,0.0,,,,,,,,,,,,,,32,1,4.0,0.4082203,0.0,0,0,0,
1627021593.011,,50000.0,16.22781,0.06698057,0.0,3,0.9974789,0.0,,,,,,,,,,,,,,32,1,4.0,0.385479,0.0,0,0,0,
1627021680.442,,50000.0,17.2009,0.06692961,0.0,3,0.9975681,0.0,,,,,,,,,,,,,,32,1,4.0,0.3796406,0.0,0,0,0,
1627021770.207,,50000.0,18.221,0.06691269,0.0,3,0.997005,0.0,,,,,,,,,,,,,,32,1,4.0,0.3887405,0.0,0,0,0,
1627021857.241,,50000.0,19.19582,0.06681137,0.0,3,0.9972728,0.0,,,,,,,,,,,,,,32,1,4.0,0.3835506,0.0,0,0,0,
1627021946.849,,50000.0,20.20958,0.06671391,0.0,3,0.997507,0.0,,,,,,,,,,,,,,32,1,4.0,0.3906803,0.0,0,0,0,
1627022035.885,,50000.0,21.18291,0.06661857,0.0,3,0.9975237,0.0,,,,,,,,,,,,,,32,1,4.0,0.35149,0.0,0,0,0,
1627022125.57,,50000.0,22.17801,0.06607857,0.0,3,0.9947253,0.0,,,,,,,,,,,,,,32,1,4.0,0.3438587,0.0,0,1,0,
1627022214.332,,50000.0,23.17869,0.0663355,0.0,3,0.9974462,0.0,,,,,,,,,,,,,,32,1,4.0,0.35252,0.0,0,1,0,
1627022306.195,,50000.0,24.17064,0.06614163,0.0,3,0.9975032,0.0,,,,,,,,,,,,,,32,1,4.0,0.3214302,0.0,0,1,0,
1627022391.835,,50000.0,25.16982,0.06594937,0.0,3,0.9975057,0.0,,,,,,,,,,,,,,32,1,4.0,0.3341904,0.0,0,1,0,
1627022488.894,,50000.0,26.19024,0.06574689,0.0,3,0.9975535,0.0,,,,,,,,,,,,,,32,1,4.0,0.3130493,0.0,0,1,0,
1627022579.305,,50000.0,27.17937,0.06549892,0.0,3,0.9973485,0.0,,,,,,,,,,,,,,32,1,4.0,0.310791,0.0,0,1,0,
1627022673.44,,50000.0,28.20377,0.06523071,0.0,3,0.997493,0.0,,,,,,,,,,,,,,32,1,4.0,0.4068508,0.0,0,1,0,
1627022759.925,,50000.0,29.20702,0.06495292,0.0,3,0.9976107,0.0,,,,,,,,,,,,,,32,1,4.0,0.3636799,0.0,0,1,0,
1627022851.008,,50000.0,30.21719,0.06462969,0.0,3,0.9974842,0.0,,,,,,,,,,,,,,32,1,4.0,0.3698997,0.0,0,1,0,
1627022943.877,,50000.0,31.26891,0.0641934,0.0,3,0.9971492,0.0,,,,,,,,,,,,,,32,1,4.0,0.4090195,0.0,0,1,0,
1627023026.515,,50000.0,32.19136,0.06392775,0.0,3,0.9975793,0.0,,,,,,,,,,,,,,32,1,4.0,0.3703613,0.0,0,1,0,
1627023119.53,,50000.0,33.19684,0.06353912,0.0,3,0.9974205,0.0,,,,,,,,,,,,,,32,1,4.0,0.3568993,0.0,0,1,0,
1627023207.519,,50000.0,34.19228,0.06310529,0.0,3,0.9973016,0.0,,,,,,,,,,,,,,32,1,4.0,0.3719406,0.0,0,1,0,
1627023302.363,,50000.0,35.19016,0.06266055,0.0,3,0.9974886,0.0,,,,,,,,,,,,,,32,1,4.0,0.37146,0.0,0,1,0,
1627023388.372,,50000.0,36.1916,0.0621787,0.0,3,0.9974664,0.0,,,,,,,,,,,,,,32,1,4.0,0.3819084,0.0,0,1,0,
1627023474.877,,50000.0,37.19669,0.06163655,0.0,3,0.9973872,0.0,,,,,,,,,,,,,,32,1,4.0,0.3283195,0.0,0,0,0,
1627023566.776,,50000.0,38.20577,0.06098076,0.0,3,0.9975242,0.0,,,,,,,,,,,,,,32,1,4.0,0.3903694,0.0,0,0,0,
1627023655.763,,50000.0,39.23864,0.05987575,0.0,3,0.9973016,0.0,,,,,,,,,,,,,,32,1,4.0,0.3662109,0.0,0,0,0,
1627023740.912,,50000.0,40.19761,0.05883273,0.0,3,0.9974986,0.0,,,,,,,,,,,,,,32,1,4.0,0.3336716,0.0,0,0,0,
1627023836.385,,50000.0,41.21713,0.05731792,0.0,3,0.9972959,0.0,,,,,,,,,,,,,,32,1,4.0,0.4104805,0.0,0,0,0,
1627023923.642,,50000.0,42.19581,0.05418916,0.0,3,0.9959149,0.0,,,,,,,,,,,,,,32,1,4.0,0.365757,0.0,0,0,0,
1627024014.679,,50000.0,43.18018,0.04759728,0.0,3,0.996676,0.0,,,,,,,,,,,,,,32,1,4.0,0.3597908,0.0,0,0,0,
1627024103.214,,50000.0,44.16157,0.04363145,0.0,3,0.9967288,0.0,,,,,,,,,,,,,,32,1,4.0,0.2999687,0.0,0,0,0,
1627024195.697,,50000.0,45.17549,0.04058393,0.0,3,0.98505,0.0,,,,,,,,,,,,,,32,1,4.0,0.3470001,0.0,0,1,0,
1627024287.192,,50000.0,46.20416,0.03999663,0.0,3,0.9972547,0.0,,,,,,,,,,,,,,32,1,4.0,0.3815002,0.0,0,1,0,
1627024376.08,,50000.0,47.19183,0.03868635,0.0,3,0.9972228,0.0,,,,,,,,,,,,,,32,1,4.0,0.3632584,0.0,0,1,0,
1627024465.56,,50000.0,48.18747,0.03751959,0.0,3,0.997115,0.0,,,,,,,,,,,,,,32,1,4.0,0.3747101,0.0,0,1,0,
1627024555.264,,50000.0,49.17719,0.036375,0.0,3,0.9972484,0.0,,,,,,,,,,,,,,32,1,4.0,0.3394318,0.0,0,1,0,
1627024643.967,,50000.0,50.18683,0.03533822,0.0,3,0.9971759,0.0,,,,,,,,,,,,,,32,1,4.0,0.3698616,0.0,0,1,0,
1627024738.004,,50000.0,51.27938,0.03417536,0.0,3,0.9970457,0.0,,,,,,,,,,,,,,32,1,4.0,0.3896713,0.0,0,1,0,
1627024819.708,,50000.0,52.19564,0.03320706,0.0,3,0.99699,0.0,,,,,,,,,,,,,,32,1,4.0,0.3667793,0.0,0,1,0,
1627024910.817,,50000.0,53.19139,0.03220001,0.0,3,0.9970273,0.0,,,,,,,,,,,,,,32,1,4.0,0.3791199,0.0,0,1,0,
1627024997.452,,50000.0,54.18532,0.03127588,0.0,3,0.9970251,0.0,,,,,,,,,,,,,,32,1,4.0,0.3499565,0.0,0,1,0,
1627025086.724,,50000.0,55.19307,0.0303859,0.0,3,0.9970603,0.0,,,,,,,,,,,,,,32,1,4.0,0.3722916,0.0,0,1,0,
1627025179.275,,50000.0,56.23337,0.02953346,0.0,3,0.9970846,0.0,,,,,,,,,,,,,,32,1,4.0,0.3869972,0.0,0,1,0,
1627025299.466,,50000.0,57.51648,0.02851553,0.0,3,0.9968199,0.0,,,,,,,,,,,,,,32,1,4.0,0.3726997,0.0,0,1,0,
1627025367.359,,50000.0,58.31701,0.02796548,0.0,3,0.9968286,0.0,,,,,,,,,,,,,,32,1,4.0,0.4507599,0.0,0,1,0,
1627025449.096,,50000.0,59.24648,0.02740367,0.0,3,0.9968655,0.0,,,,,,,,,,,,,,32,1,4.0,0.3049889,0.0,0,1,0,
1627025679.911,,50000.0,60.04122,0.02674595,0.0,3,0.9969689,0.0,,,,,,,,,,,,,,32,1,4.0,0.08744049,0.0,0,0,0,
1627057259.861,,40000.0,10.68694,0.0669841,0.0,3,0.9969859,0.0,,,,,,,,,,,,,,32,1,4.0,0.3322105,0.0,0,1,0,
1627057355.431,,40000.0,11.69055,0.06704859,0.0,3,0.9974369,0.0,,,,,,,,,,,,,,32,1,4.0,0.3262997,0.0,0,0,0,
1627057450.311,,40000.0,12.69328,0.06704108,0.0,3,0.9975473,0.0,,,,,,,,,,,,,,32,1,4.0,0.3693304,0.0,0,0,0,
1627057541.871,,40000.0,13.71356,0.06703047,0.0,3,0.9974537,0.0,,,,,,,,,,,,,,32,1,4.0,0.3727598,0.0,0,0,0,
1627057629.582,,40000.0,14.69502,0.06700601,0.0,3,0.997395,0.0,,,,,,,,,,,,,,32,1,4.0,0.3797293,0.0,0,0,0,
1627057720.612,,40000.0,15.7131,0.06696772,0.0,3,0.9974196,0.0,,,,,,,,,,,,,,32,1,4.0,0.3986597,0.0,0,0,0,
1627057806.563,,40000.0,16.68855,0.06690845,0.0,3,0.9974679,0.0,,,,,,,,,,,,,,32,1,4.0,0.36763,0.0,0,0,0,
1627057900.693,,40000.0,17.71223,0.06684694,0.0,3,0.9975963,0.0,,,,,,,,,,,,,,32,1,4.0,0.3945999,0.0,0,0,0,
1627057989.294,,40000.0,18.70475,0.06678136,0.0,3,0.9974988,0.0,,,,,,,,,,,,,,32,1,4.0,0.3728085,0.0,0,0,0,
1627058075.855,,40000.0,19.72628,0.06669113,0.0,3,0.9976931,0.0,,,,,,,,,,,,,,32,1,4.0,0.4372501,0.0,0,1,0,
1627058163.956,,40000.0,20.68075,0.06656057,0.0,3,0.9976287,0.0,,,,,,,,,,,,,,32,1,4.0,0.39394,0.0,0,1,0,
1627058254.586,,40000.0,21.70428,0.06642986,0.0,3,0.9975569,0.0,,,,,,,,,,,,,,32,1,4.0,0.3410912,0.0,0,1,0,
1627058346.717,,40000.0,22.7091,0.06640499,0.0,3,0.9970849,0.0,,,,,,,,,,,,,,32,1,4.0,0.3805313,0.0,0,1,0,
1627058429.748,,40000.0,23.66885,0.06607845,0.0,3,0.9975502,0.0,,,,,,,,,,,,,,32,1,4.0,0.3030109,0.0,0,1,0,
1627058516.799,,40000.0,24.67393,0.06586267,0.0,3,0.9974974,0.0,,,,,,,,,,,,,,32,1,4.0,0.3385201,0.0,0,1,0,
1627058605.979,,40000.0,25.687,0.06564074,0.0,3,0.9975197,0.0,,,,,,,,,,,,,,32,1,4.0,0.3251514,0.0,0,1,0,
1627058699.779,,40000.0,26.70617,0.06538182,0.0,3,0.9974782,0.0,,,,,,,,,,,,,,32,1,4.0,0.3708706,0.0,0,1,0,
1627058784.211,,40000.0,27.70548,0.06509522,0.0,3,0.9974301,0.0,,,,,,,,,,,,,,32,1,4.0,0.3764305,0.0,0,1,0,
1627058878.471,,40000.0,28.69864,0.06479041,0.0,3,0.9974931,0.0,,,,,,,,,,,,,,32,1,4.0,0.3387699,0.0,0,1,0,
1627058968.671,,40000.0,29.70934,0.06443675,0.0,3,0.9974462,0.0,,,,,,,,,,,,,,32,1,4.0,0.3273296,0.0,0,1,0,
1627059066.121,,40000.0,30.8504,0.06401207,0.0,3,0.9974714,0.0,,,,,,,,,,,,,,32,1,4.0,0.4090309,0.0,0,1,0,
1627059144.163,,40000.0,31.70828,0.06369625,0.0,3,0.9975229,0.0,,,,,,,,,,,,,,32,1,4.0,0.4066696,0.0,0,1,0,
1627059232.133,,40000.0,32.70377,0.06322662,0.0,3,0.9974276,0.0,,,,,,,,,,,,,,32,1,4.0,0.3547096,0.0,0,1,0,
1627059314.955,,40000.0,33.64211,0.06290399,0.0,3,0.9975832,0.0,,,,,,,,,,,,,,32,1,4.0,0.2519493,0.0,0,1,0,
1627059409.375,,40000.0,34.6805,0.06228702,0.0,3,0.9976062,0.0,,,,,,,,,,,,,,32,1,4.0,0.3344307,0.0,0,0,0,
1627059493.016,,40000.0,35.72304,0.06176683,0.0,3,0.9973461,0.0,,,,,,,,,,,,,,32,1,4.0,0.3984489,0.0,0,0,0,
1627059585.486,,40000.0,36.69798,0.06113061,0.0,3,0.9973505,0.0,,,,,,,,,,,,,,32,1,4.0,0.3828583,0.0,0,0,0,
1627059673.857,,40000.0,37.72723,0.06029543,0.0,3,0.9973861,0.0,,,,,,,,,,,,,,32,1,4.0,0.3786507,0.0,0,0,0,
1627059759.868,,40000.0,38.73041,0.05878621,0.0,3,0.9973387,0.0,,,,,,,,,,,,,,32,1,4.0,0.4391594,0.0,0,0,0,
1627059845.289,,40000.0,39.69231,0.05716541,0.0,3,0.9970442,0.0,,,,,,,,,,,,,,32,1,4.0,0.3663292,0.0,0,0,0,
1627059932.78,,40000.0,40.69746,0.05282065,0.0,3,0.9949612,0.0,,,,,,,,,,,,,,32,1,4.0,0.3888893,0.0,0,0,0,
1627060023.2,,40000.0,41.70675,0.04359889,0.0,3,0.9953848,0.0,,,,,,,,,,,,,,32,1,4.0,0.3913498,0.0,0,0,0,
1627060110.301,,40000.0,42.73255,0.03958192,0.0,3,0.9968154,0.0,,,,,,,,,,,,,,32,1,4.0,0.2776794,0.0,0,0,0,
1627060192.882,,40000.0,43.6892,0.03785616,0.0,3,0.9970354,0.0,,,,,,,,,,,,,,32,1,4.0,0.3157997,0.0,0,1,0,
1627060281.393,,40000.0,44.65486,0.0364076,0.0,3,0.9970289,0.0,,,,,,,,,,,,,,32,1,4.0,0.2984428,0.0,0,1,0,
1627060374.333,,40000.0,45.69521,0.03495251,0.0,3,0.9971105,0.0,,,,,,,,,,,,,,32,1,4.0,0.3772316,0.0,0,1,0,
1627060453.485,,40000.0,46.59101,0.03379383,0.0,3,0.9969987,0.0,,,,,,,,,,,,,,32,1,4.0,0.4239388,0.0,0,1,0,
1627060550.065,,40000.0,47.76797,0.03253674,0.0,3,0.9971929,0.0,,,,,,,,,,,,,,32,1,4.0,0.285862,0.0,0,1,0,
1627060636.756,,40000.0,48.6682,0.03152315,0.0,3,0.9972515,0.0,,,,,,,,,,,,,,32,1,4.0,0.3126183,0.0,0,1,0,
1627060722.017,,40000.0,49.69617,0.03054782,0.0,3,0.9971766,0.0,,,,,,,,,,,,,,32,1,4.0,0.2937317,0.0,0,1,0,
1627060824.516,,40000.0,50.78235,0.0294394,0.0,3,0.9971842,0.0,,,,,,,,,,,,,,32,1,4.0,0.3868217,0.0,0,1,0,
1627060902.698,,40000.0,51.71367,0.02855095,0.0,3,0.9970672,0.0,,,,,,,,,,,,,,32,1,4.0,0.3340187,0.0,0,1,0,
1627060990.548,,40000.0,52.69239,0.02760019,0.0,3,0.9970888,0.0,,,,,,,,,,,,,,32,1,4.0,0.3788605,0.0,0,1,0,
1627061081.699,,40000.0,53.71478,0.02674156,0.0,3,0.9971589,0.0,,,,,,,,,,,,,,32,1,4.0,0.2523308,0.0,0,1,0,
1627061175.819,,40000.0,54.70493,0.02593213,0.0,3,0.9970492,0.0,,,,,,,,,,,,,,32,1,4.0,0.266922,0.0,0,1,0,
1627061266.179,,40000.0,55.67877,0.02515213,0.0,3,0.9969813,0.0,,,,,,,,,,,,,,32,1,4.0,0.3518715,0.0,0,1,0,
1627061347.211,,40000.0,56.64271,0.02448633,0.0,3,0.9968219,0.0,,,,,,,,,,,,,,32,1,4.0,0.270359,0.0,0,1,0,
1627061443.661,,40000.0,57.72646,0.02381101,0.0,3,0.9961804,0.0,,,,,,,,,,,,,,32,1,4.0,0.2982292,0.0,0,1,0,
1627061529.792,,40000.0,58.6889,0.02310869,0.0,3,0.9969423,0.0,,,,,,,,,,,,,,32,1,4.0,0.3599091,0.0,0,0,0,
1627061617.223,,40000.0,59.72327,0.02248365,0.0,3,0.9968703,0.0,,,,,,,,,,,,,,32,1,4.0,0.3242493,0.0,0,0,0,
1627093428.307,,30000.0,10.00032,0.06695937,0.0,3,0.9973209,0.0,,,,,,,,,,,,,,32,1,4.0,0.01981926,0.0,0,0,0,
1627093559.983,,30000.0,11.17007,0.06700935,0.0,3,0.9973454,0.0,,,,,,,,,,,,,,32,1,4.0,0.3229198,0.0,0,1,0,
1627093657.162,,30000.0,12.19908,0.06693427,0.0,3,0.997435,0.0,,,,,,,,,,,,,,32,1,4.0,0.3203402,0.0,0,1,0,
1627093748.973,,30000.0,13.21935,0.06691679,0.0,3,0.9974956,0.0,,,,,,,,,,,,,,32,1,4.0,0.3724298,0.0,0,1,0,
1627093840.103,,30000.0,14.21163,0.06688654,0.0,3,0.9975652,0.0,,,,,,,,,,,,,,32,1,4.0,0.4067898,0.0,0,1,0,
1627093925.624,,30000.0,15.17342,0.06685821,0.0,3,0.9973906,0.0,,,,,,,,,,,,,,32,1,4.0,0.3353405,0.0,0,1,0,
1627094015.625,,30000.0,16.22486,0.06680659,0.0,3,0.9975322,0.0,,,,,,,,,,,,,,32,1,4.0,0.3951111,0.0,0,1,0,
1627094103.066,,30000.0,17.21404,0.06675121,0.0,3,0.9974132,0.0,,,,,,,,,,,,,,32,1,4.0,0.3617191,0.0,0,1,0,
1627094193.316,,30000.0,18.19117,0.06666332,0.0,3,0.997345,0.0,,,,,,,,,,,,,,32,1,4.0,0.3678303,0.0,0,1,0,
1627094280.737,,30000.0,19.19352,0.06656279,0.0,3,0.997499,0.0,,,,,,,,,,,,,,32,1,4.0,0.35919,0.0,0,0,0,
1627094370.447,,30000.0,20.212,0.06642364,0.0,3,0.9974798,0.0,,,,,,,,,,,,,,32,1,4.0,0.4045601,0.0,0,0,0,
1627094456.468,,30000.0,21.21539,0.06629388,0.0,3,0.9974235,0.0,,,,,,,,,,,,,,32,1,4.0,0.33741,0.0,0,0,0,
1627094545.619,,30000.0,22.1913,0.06612619,0.0,3,0.9975201,0.0,,,,,,,,,,,,,,32,1,4.0,0.3747196,0.0,0,0,0,
1627094633.39,,30000.0,23.17984,0.06591648,0.0,3,0.9974226,0.0,,,,,,,,,,,,,,32,1,4.0,0.3478394,0.0,0,0,0,
1627094727.11,,30000.0,24.18856,0.06568664,0.0,3,0.9974729,0.0,,,,,,,,,,,,,,32,1,4.0,0.3421993,0.0,0,0,0,
1627094814.621,,30000.0,25.1981,0.06543946,0.0,3,0.9974053,0.0,,,,,,,,,,,,,,32,1,4.0,0.37994,0.0,0,0,0,
1627094901.572,,30000.0,26.15208,0.06518961,0.0,3,0.997959,0.0,,,,,,,,,,,,,,32,1,4.0,0.2801495,0.0,0,0,0,
1627094996.272,,30000.0,27.18978,0.06484896,0.0,3,0.9973884,0.0,,,,,,,,,,,,,,32,1,4.0,0.3563213,0.0,0,1,0,
1627095084.622,,30000.0,28.17416,0.06452492,0.0,3,0.9975001,0.0,,,,,,,,,,,,,,32,1,4.0,0.3278713,0.0,0,1,0,
1627095177.453,,30000.0,29.215,0.06414551,0.0,3,0.997395,0.0,,,,,,,,,,,,,,32,1,4.0,0.3620892,0.0,0,1,0,
1627095265.473,,30000.0,30.2382,0.06373863,0.0,3,0.997384,0.0,,,,,,,,,,,,,,32,1,4.0,0.3507309,0.0,0,1,0,
1627095354.484,,30000.0,31.24627,0.06329806,0.0,3,0.9974384,0.0,,,,,,,,,,,,,,32,1,4.0,0.3542614,0.0,0,1,0,
1627095438.415,,30000.0,32.19302,0.06286159,0.0,3,0.9974144,0.0,,,,,,,,,,,,,,32,1,4.0,0.3670311,0.0,0,1,0,
1627095530.515,,30000.0,33.21063,0.06233725,0.0,3,0.9974097,0.0,,,,,,,,,,,,,,32,1,4.0,0.3704491,0.0,0,1,0,
1627095618.596,,30000.0,34.18098,0.06181706,0.0,3,0.9973693,0.0,,,,,,,,,,,,,,32,1,4.0,0.3456421,0.0,0,1,0,
1627095702.837,,30000.0,35.161,0.06123683,0.0,3,0.9972603,0.0,,,,,,,,,,,,,,32,1,4.0,0.3112297,0.0,0,1,0,
1627095798.907,,30000.0,36.19868,0.06048641,0.0,3,0.997426,0.0,,,,,,,,,,,,,,32,1,4.0,0.3552475,0.0,0,1,0,
1627095883.638,,30000.0,37.19134,0.05917548,0.0,3,0.9971508,0.0,,,,,,,,,,,,,,32,1,4.0,0.3390312,0.0,0,1,0,
1627095976.489,,30000.0,38.20969,0.05663135,0.0,3,0.9967959,0.0,,,,,,,,,,,,,,32,1,4.0,0.380249,0.0,0,1,0,
1627096066.659,,30000.0,39.18777,0.04889911,0.0,3,0.9906319,0.0,,,,,,,,,,,,,,32,1,4.0,0.3724785,0.0,0,1,0,
1627096155.04,,30000.0,40.20989,0.03740839,0.0,3,0.9953751,0.0,,,,,,,,,,,,,,32,1,4.0,0.3140602,0.0,0,1,0,
1627096247.77,,30000.0,41.22482,0.03457993,0.0,3,0.9970729,0.0,,,,,,,,,,,,,,32,1,4.0,0.3977013,0.0,0,1,0,
1627096335.621,,30000.0,42.20113,0.03301825,0.0,3,0.9970635,0.0,,,,,,,,,,,,,,32,1,4.0,0.3496895,0.0,0,0,0,
1627096425.381,,30000.0,43.20558,0.03148976,0.0,3,0.9969704,0.0,,,,,,,,,,,,,,32,1,4.0,0.4078026,0.0,0,0,0,
1627096521.301,,30000.0,44.1917,0.03011172,0.0,3,0.9970903,0.0,,,,,,,,,,,,,,32,1,4.0,0.3805008,0.0,0,0,0,
1627096610.692,,30000.0,45.2158,0.02883958,0.0,3,0.9970056,0.0,,,,,,,,,,,,,,32,1,4.0,0.3824501,0.0,0,0,0,
1627096700.312,,30000.0,46.20332,0.02773005,0.0,3,0.9970949,0.0,,,,,,,,,,,,,,32,1,4.0,0.3673019,0.0,0,0,0,
1627096789.783,,30000.0,47.19669,0.02667542,0.0,3,0.9971411,0.0,,,,,,,,,,,,,,32,1,4.0,0.3502312,0.0,0,0,0,
1627096880.343,,30000.0,48.20284,0.02568971,0.0,3,0.9970639,0.0,,,,,,,,,,,,,,32,1,4.0,0.3986893,0.0,0,0,0,
1627096961.085,,30000.0,49.15948,0.02484273,0.0,3,0.9969079,0.0,,,,,,,,,,,,,,32,1,4.0,0.29702,0.0,0,0,0,
1627097049.256,,30000.0,50.16293,0.02396849,0.0,3,0.9968984,0.0,,,,,,,,,,,,,,32,1,4.0,0.2894516,0.0,0,0,0,
1627097147.425,,30000.0,51.20277,0.02305815,0.0,3,0.997088,0.0,,,,,,,,,,,,,,32,1,4.0,0.3565712,0.0,0,1,0,
1627097232.706,,30000.0,52.19443,0.02226472,0.0,3,0.9960842,0.0,,,,,,,,,,,,,,32,1,4.0,0.2789803,0.0,0,1,0,
1627097319.247,,30000.0,53.16605,0.02154249,0.0,3,0.9968892,0.0,,,,,,,,,,,,,,32,1,4.0,0.3284302,0.0,0,1,0,
1627097419.637,,30000.0,54.25447,0.02072127,0.0,3,0.9969317,0.0,,,,,,,,,,,,,,32,1,4.0,0.4551086,0.0,0,1,0,
1627097506.838,,30000.0,55.18436,0.02007426,0.0,3,0.9968774,0.0,,,,,,,,,,,,,,32,1,4.0,0.3377495,0.0,0,1,0,
1627097594.658,,30000.0,56.16988,0.0194653,0.0,3,0.9970223,0.0,,,,,,,,,,,,,,32,1,4.0,0.3307419,0.0,0,1,0,
1627097685.549,,30000.0,57.18474,0.01887089,0.0,3,0.9968746,0.0,,,,,,,,,,,,,,32,1,4.0,0.3368187,0.0,0,1,0,
1627097775.989,,30000.0,58.19337,0.01832661,0.0,3,0.996926,0.0,,,,,,,,,,,,,,32,1,4.0,0.2647095,0.0,0,1,0,
1627097869.409,,30000.0,59.21742,0.01777461,0.0,3,0.9969859,0.0,,,,,,,,,,,,,,32,1,4.0,0.38274,0.0,0,1,0,
1627098098.925,,30000.0,60.00124,0.0173615,0.0,3,0.9969569,0.0,,,,,,,,,,,,,,32,1,4.0,0.007488251,0.0,0,1,0,
1627130038.386,,20000.0,10.68989,0.06655053,0.0,3,0.9973642,0.0,,,,,,,,,,,,,,32,1,4.0,0.3505993,0.0,0,1,0,
1627130129.097,,20000.0,11.67648,0.06653555,0.0,3,0.9972627,0.0,,,,,,,,,,,,,,32,1,4.0,0.3156595,0.0,0,1,0,
1627130226.337,,20000.0,12.68594,0.06651354,0.0,3,0.9973433,0.0,,,,,,,,,,,,,,32,1,4.0,0.3663998,0.0,0,1,0,
1627130314.657,,20000.0,13.72535,0.06649594,0.0,3,0.9974213,0.0,,,,,,,,,,,,,,32,1,4.0,0.4047098,0.0,0,1,0,
1627130404.858,,20000.0,14.70417,0.06645641,0.0,3,0.9973422,0.0,,,,,,,,,,,,,,32,1,4.0,0.4058704,0.0,0,0,0,
1627130495.558,,20000.0,15.71203,0.06640516,0.0,3,0.9972993,0.0,,,,,,,,,,,,,,32,1,4.0,0.3561792,0.0,0,0,0,
1627130585.359,,20000.0,16.71124,0.06634293,0.0,3,0.9972862,0.0,,,,,,,,,,,,,,32,1,4.0,0.4054298,0.0,0,0,0,
1627130675.239,,20000.0,17.70116,0.06625271,0.0,3,0.9973143,0.0,,,,,,,,,,,,,,32,1,4.0,0.3696499,0.0,0,0,0,
1627130765.4,,20000.0,18.6854,0.06615235,0.0,3,0.997336,0.0,,,,,,,,,,,,,,32,1,4.0,0.349781,0.0,0,0,0,
1627130855.01,,20000.0,19.70983,0.06600847,0.0,3,0.9974581,0.0,,,,,,,,,,,,,,32,1,4.0,0.3698406,0.0,0,0,0,
1627130941.531,,20000.0,20.68579,0.06586445,0.0,3,0.9975061,0.0,,,,,,,,,,,,,,32,1,4.0,0.3663101,0.0,0,0,0,
1627131037.111,,20000.0,21.68426,0.06567446,0.0,3,0.9975027,0.0,,,,,,,,,,,,,,32,1,4.0,0.3175411,0.0,0,0,0,
1627131128.292,,20000.0,22.69943,0.06545958,0.0,3,0.9974664,0.0,,,,,,,,,,,,,,32,1,4.0,0.3791008,0.0,0,1,0,
1627131217.072,,20000.0,23.67707,0.06522758,0.0,3,0.9973921,0.0,,,,,,,,,,,,,,32,1,4.0,0.3436298,0.0,0,1,0,
1627131305.143,,20000.0,24.67797,0.06496117,0.0,3,0.9975092,0.0,,,,,,,,,,,,,,32,1,4.0,0.3517914,0.0,0,1,0,
1627131394.304,,20000.0,25.66154,0.06465789,0.0,3,0.9972191,0.0,,,,,,,,,,,,,,32,1,4.0,0.3161087,0.0,0,1,0,
1627131485.734,,20000.0,26.68411,0.06432318,0.0,3,0.9972321,0.0,,,,,,,,,,,,,,32,1,4.0,0.3506794,0.0,0,1,0,
1627131576.585,,20000.0,27.68596,0.06397038,0.0,3,0.997368,0.0,,,,,,,,,,,,,,32,1,4.0,0.3501511,0.0,0,1,0,
1627131666.615,,20000.0,28.69287,0.06355005,0.0,3,0.9969646,0.0,,,,,,,,,,,,,,32,1,4.0,0.3850708,0.0,0,1,0,
1627131753.706,,20000.0,29.68659,0.06314947,0.0,3,0.9973041,0.0,,,,,,,,,,,,,,32,1,4.0,0.346981,0.0,0,1,0,
1627131857.165,,20000.0,30.83028,0.06259172,0.0,3,0.9975003,0.0,,,,,,,,,,,,,,32,1,4.0,0.3656998,0.0,0,1,0,
1627131933.957,,20000.0,31.72565,0.06216366,0.0,3,0.9973813,0.0,,,,,,,,,,,,,,32,1,4.0,0.362011,0.0,0,1,0,
1627132019.008,,20000.0,32.69312,0.06163324,0.0,3,0.9973126,0.0,,,,,,,,,,,,,,32,1,4.0,0.3812485,0.0,0,1,0,
1627132108.009,,20000.0,33.68538,0.06101443,0.0,3,0.9973983,0.0,,,,,,,,,,,,,,32,1,4.0,0.3474808,0.0,0,1,0,
1627132201.379,,20000.0,34.71995,0.0603408,0.0,3,0.9973523,0.0,,,,,,,,,,,,,,32,1,4.0,0.3867798,0.0,0,1,0,
1627132287.15,,20000.0,35.67434,0.0593047,0.0,3,0.995782,0.0,,,,,,,,,,,,,,32,1,4.0,0.2891006,0.0,0,1,0,
1627132382.3,,20000.0,36.70646,0.05520769,0.0,3,0.9958108,0.0,,,,,,,,,,,,,,32,1,4.0,0.2511292,0.0,0,0,0,
1627132477.34,,20000.0,37.7035,0.03568985,0.0,3,0.9852484,0.0,,,,,,,,,,,,,,32,1,4.0,0.3926201,0.0,0,0,0,
1627132562.231,,20000.0,38.74162,0.02989436,0.0,3,0.9966679,0.0,,,,,,,,,,,,,,32,1,4.0,0.4799309,0.0,0,0,0,
1627132683.618,,20000.0,40.09656,0.02732609,0.0,3,0.9967969,0.0,,,,,,,,,,,,,,32,1,4.0,0.3519096,0.0,0,0,0,
1627132755.331,,20000.0,40.93161,0.02606799,0.0,3,0.9966313,0.0,,,,,,,,,,,,,,32,1,4.0,0.3966217,0.0,0,0,0,
1627132827.693,,20000.0,41.72585,0.02492998,0.0,3,0.996815,0.0,,,,,,,,,,,,,,32,1,4.0,0.3903389,0.0,0,0,0,
1627132907.185,,20000.0,42.67084,0.02377959,0.0,3,0.9966847,0.0,,,,,,,,,,,,,,32,1,4.0,0.3016777,0.0,0,0,0,
1627133002.725,,20000.0,43.6893,0.02253894,0.0,3,0.9971241,0.0,,,,,,,,,,,,,,32,1,4.0,0.3443794,0.0,0,0,0,
1627133093.125,,20000.0,44.71696,0.02146026,0.0,3,0.9970033,0.0,,,,,,,,,,,,,,32,1,4.0,0.4137688,0.0,0,0,0,
1627133181.716,,20000.0,45.6967,0.0204917,0.0,3,0.9971656,0.0,,,,,,,,,,,,,,32,1,4.0,0.3586998,0.0,0,1,0,
1627133271.356,,20000.0,46.78429,0.01960297,0.0,3,0.9969926,0.0,,,,,,,,,,,,,,32,1,4.0,0.3738594,0.0,0,1,0,
1627133359.967,,20000.0,47.6888,0.01880602,0.0,3,0.9971219,0.0,,,,,,,,,,,,,,32,1,4.0,0.3266869,0.0,0,1,0,
1627133443.578,,20000.0,48.62189,0.01804688,0.0,3,0.9968904,0.0,,,,,,,,,,,,,,32,1,4.0,0.4017715,0.0,0,1,0,
1627133531.469,,20000.0,49.67285,0.01735583,0.0,3,0.9969616,0.0,,,,,,,,,,,,,,32,1,4.0,0.2720222,0.0,0,1,0,
1627133641.647,,20000.0,50.90266,0.01654247,0.0,3,0.9972442,0.0,,,,,,,,,,,,,,32,1,4.0,0.4201584,0.0,0,1,0,
1627133711.73,,20000.0,51.69914,0.01603496,0.0,3,0.9970735,0.0,,,,,,,,,,,,,,32,1,4.0,0.2820396,0.0,0,1,0,
1627133804.6,,20000.0,52.69337,0.01539307,0.0,3,0.996861,0.0,,,,,,,,,,,,,,32,1,4.0,0.3729286,0.0,0,1,0,
1627133892.801,,20000.0,53.73373,0.01481069,0.0,3,0.9972025,0.0,,,,,,,,,,,,,,32,1,4.0,0.4208107,0.0,0,1,0,
1627134013.818,,20000.0,55.08229,0.01409902,0.0,3,0.9969426,0.0,,,,,,,,,,,,,,32,1,4.0,0.3173599,0.0,0,1,0,
1627134082.061,,20000.0,55.90498,0.01372924,0.0,3,0.9967356,0.0,,,,,,,,,,,,,,32,1,4.0,0.4468498,0.0,0,1,0,
1627134152.184,,20000.0,56.66525,0.01338521,0.0,3,0.9969513,0.0,,,,,,,,,,,,,,32,1,4.0,0.2705536,0.0,0,1,0,
1627134243.964,,20000.0,57.68707,0.0129485,0.0,3,0.996864,0.0,,,,,,,,,,,,,,32,1,4.0,0.367691,0.0,0,1,0,
1627134339.424,,20000.0,58.78656,0.01253643,0.0,3,0.996976,0.0,,,,,,,,,,,,,,32,1,4.0,0.4644394,0.0,0,1,0,
1627134428.325,,20000.0,59.72111,0.01217813,0.0,3,0.9969241,0.0,,,,,,,,,,,,,,32,1,4.0,0.4331017,0.0,0,0,0,
1627166462.495,,10000.0,9.999769,0.06505974,0.0,3,0.9974189,0.0,,,,,,,,,,,,,,32,1,4.0,0.001721382,0.0,0,1,0,
1627166593.701,,10000.0,11.16778,0.0650456,0.0,3,0.9974958,0.0,,,,,,,,,,,,,,32,1,4.0,0.3202705,0.0,0,1,0,
1627166688.951,,10000.0,12.18445,0.06503607,0.0,3,0.9975529,0.0,,,,,,,,,,,,,,32,1,4.0,0.3464298,0.0,0,1,0,
1627166777.992,,10000.0,13.20086,0.06500447,0.0,3,0.9973589,0.0,,,,,,,,,,,,,,32,1,4.0,0.3853703,0.0,0,1,0,
1627166866.953,,10000.0,14.1865,0.06505191,0.0,3,0.9970122,0.0,,,,,,,,,,,,,,32,1,4.0,0.3557005,0.0,0,0,0,
1627166960.613,,10000.0,15.22379,0.06491427,0.0,3,0.9973627,0.0,,,,,,,,,,,,,,32,1,4.0,0.3709402,0.0,0,0,0,
1627167044.614,,10000.0,16.17566,0.06485305,0.0,3,0.997402,0.0,,,,,,,,,,,,,,32,1,4.0,0.3490696,0.0,0,0,0,
1627167133.115,,10000.0,17.19202,0.06475681,0.0,3,0.9974226,0.0,,,,,,,,,,,,,,32,1,4.0,0.3792706,0.0,0,0,0,
1627167222.425,,10000.0,18.17931,0.06465404,0.0,3,0.9974037,0.0,,,,,,,,,,,,,,32,1,4.0,0.3545094,0.0,0,0,0,
1627167310.456,,10000.0,19.17451,0.06452359,0.0,3,0.9973831,0.0,,,,,,,,,,,,,,32,1,4.0,0.3359814,0.0,0,0,0,
1627167404.646,,10000.0,20.20766,0.06436329,0.0,3,0.9972758,0.0,,,,,,,,,,,,,,32,1,4.0,0.3814201,0.0,0,0,0,
1627167495.657,,10000.0,21.18682,0.06416947,0.0,3,0.9974411,0.0,,,,,,,,,,,,,,32,1,4.0,0.3395901,0.0,0,0,0,
1627167584.857,,10000.0,22.18566,0.06384638,0.0,3,0.9951569,0.0,,,,,,,,,,,,,,32,1,4.0,0.3484211,0.0,0,1,0,
1627167676.038,,10000.0,23.20542,0.06369316,0.0,3,0.9974577,0.0,,,,,,,,,,,,,,32,1,4.0,0.2870998,0.0,0,1,0,
1627167767.848,,10000.0,24.188,0.0634101,0.0,3,0.9973186,0.0,,,,,,,,,,,,,,32,1,4.0,0.3536396,0.0,0,1,0,
1627167855.989,,10000.0,25.18629,0.06310128,0.0,3,0.9974353,0.0,,,,,,,,,,,,,,32,1,4.0,0.3482285,0.0,0,1,0,
1627167944.309,,10000.0,26.18596,0.06275178,0.0,3,0.9974383,0.0,,,,,,,,,,,,,,32,1,4.0,0.3334312,0.0,0,1,0,
1627168035.27,,10000.0,27.18275,0.06236764,0.0,3,0.9972635,0.0,,,,,,,,,,,,,,32,1,4.0,0.3577099,0.0,0,1,0,
1627168121.611,,10000.0,28.1973,0.06195427,0.0,3,0.9973764,0.0,,,,,,,,,,,,,,32,1,4.0,0.2916794,0.0,0,1,0,
1627168211.621,,10000.0,29.18399,0.06149108,0.0,3,0.9974083,0.0,,,,,,,,,,,,,,32,1,4.0,0.3667202,0.0,0,1,0,
1627168302.292,,10000.0,30.20889,0.06100876,0.0,3,0.9974013,0.0,,,,,,,,,,,,,,32,1,4.0,0.28615,0.0,0,1,0,
1627168393.602,,10000.0,31.23046,0.06046502,0.0,3,0.9974579,0.0,,,,,,,,,,,,,,32,1,4.0,0.3810501,0.0,0,1,0,
1627168480.323,,10000.0,32.23267,0.05987641,0.0,3,0.9973956,0.0,,,,,,,,,,,,,,32,1,4.0,0.3013306,0.0,0,1,0,
1627168567.604,,10000.0,33.16623,0.05922503,0.0,3,0.9975465,0.0,,,,,,,,,,,,,,32,1,4.0,0.3377686,0.0,0,1,0,
1627168660.574,,10000.0,34.22169,0.05812258,0.0,3,0.9964175,0.0,,,,,,,,,,,,,,32,1,4.0,0.375309,0.0,0,1,0,
1627168748.725,,10000.0,35.20325,0.0466698,0.0,3,0.9825048,0.0,,,,,,,,,,,,,,32,1,4.0,0.341301,0.0,0,1,0,
1627168864.752,,10000.0,36.48416,0.02145918,0.0,3,0.9963004,0.0,,,,,,,,,,,,,,32,1,4.0,0.43116,0.0,0,0,0,
1627168938.235,,10000.0,37.31989,0.01993411,0.0,3,0.9964404,0.0,,,,,,,,,,,,,,32,1,4.0,0.3899689,0.0,0,0,0,
1627169020.096,,10000.0,38.22968,0.01849418,0.0,3,0.9966954,0.0,,,,,,,,,,,,,,32,1,4.0,0.4202385,0.0,0,0,0,
1627169100.778,,10000.0,39.1892,0.01717745,0.0,3,0.9967189,0.0,,,,,,,,,,,,,,32,1,4.0,0.276722,0.0,0,0,0,
1627169196.808,,10000.0,40.18281,0.01597766,0.0,3,0.99665,0.0,,,,,,,,,,,,,,32,1,4.0,0.3433418,0.0,0,0,0,
1627169291.108,,10000.0,41.19047,0.01484403,0.0,3,0.996832,0.0,,,,,,,,,,,,,,32,1,4.0,0.3571587,0.0,0,0,0,
1627169410.175,,10000.0,42.52289,0.01362401,0.0,3,0.9965941,0.0,,,,,,,,,,,,,,32,1,4.0,0.404789,0.0,0,0,0,
1627169482.168,,10000.0,43.31577,0.01296664,0.0,3,0.9967633,0.0,,,,,,,,,,,,,,32,1,4.0,0.3913193,0.0,0,0,0,
1627169560.539,,10000.0,44.18141,0.01232238,0.0,3,0.9968234,0.0,,,,,,,,,,,,,,32,1,4.0,0.357029,0.0,0,0,0,
1627169650.82,,10000.0,45.19839,0.01164805,0.0,3,0.9968837,0.0,,,,,,,,,,,,,,32,1,4.0,0.3927994,0.0,0,1,0,
1627169738.191,,10000.0,46.17488,0.01104244,0.0,3,0.9968526,0.0,,,,,,,,,,,,,,32,1,4.0,0.3417015,0.0,0,1,0,
1627169829.731,,10000.0,47.20874,0.0105477,0.0,3,0.9948677,0.0,,,,,,,,,,,,,,32,1,4.0,0.2734299,0.0,0,1,0,
1627169918.702,,10000.0,48.20704,0.01001596,0.0,3,0.996927,0.0,,,,,,,,,,,,,,32,1,4.0,0.3868599,0.0,0,1,0,
1627170003.163,,10000.0,49.1834,0.009584079,0.0,3,0.9969618,0.0,,,,,,,,,,,,,,32,1,4.0,0.3553314,0.0,0,1,0,
1627170089.724,,10000.0,50.22305,0.009174296,0.0,3,0.9968339,0.0,,,,,,,,,,,,,,32,1,4.0,0.2827606,0.0,0,1,0,
1627170181.234,,10000.0,51.20255,0.008799028,0.0,3,0.9968216,0.0,,,,,,,,,,,,,,32,1,4.0,0.2773476,0.0,0,1,0,
1627170273.864,,10000.0,52.22176,0.008424237,0.0,3,0.9968054,0.0,,,,,,,,,,,,,,32,1,4.0,0.2831306,0.0,0,1,0,
1627170365.195,,10000.0,53.20658,0.008087972,0.0,3,0.9970851,0.0,,,,,,,,,,,,,,32,1,4.0,0.4015121,0.0,0,1,0,
1627170448.236,,10000.0,54.18951,0.007713715,0.0,3,0.9900546,0.0,,,,,,,,,,,,,,32,1,4.0,0.3583298,0.0,0,1,0,
1627170537.607,,10000.0,55.18118,0.0074996,0.0,3,0.9968966,0.0,,,,,,,,,,,,,,32,1,4.0,0.3527794,0.0,0,1,0,
1627170625.887,,10000.0,56.19987,0.007244266,0.0,3,0.9969193,0.0,,,,,,,,,,,,,,32,1,4.0,0.333271,0.0,0,1,0,
1627170731.956,,10000.0,57.39716,0.006955187,0.0,3,0.9968175,0.0,,,,,,,,,,,,,,32,1,4.0,0.2352486,0.0,0,1,0,
1627170804.998,,10000.0,58.18172,0.006773189,0.0,3,0.9969706,0.0,,,,,,,,,,,,,,32,1,4.0,0.3354988,0.0,0,1,0,
1627170892.439,,10000.0,59.20036,0.006563195,0.0,3,0.9968919,0.0,,,,,,,,,,,,,,32,1,4.0,0.3825607,0.0,0,0,0,
1627171121.505,,10000.0,60.04748,0.006397041,0.0,3,0.9971239,0.0,,,,,,,,,,,,,,32,1,4.0,0.09996033,0.0,0,0,0,
1627181105.895,,6000.0,10.6762,0.06332833,0.0,3,0.9972497,0.0,,,,,,,,,,,,,,32,1,4.0,0.3474302,0.0,0,0,0,
1627181197.755,,6000.0,11.68755,0.06332298,0.0,3,0.9972056,0.0,,,,,,,,,,,,,,32,1,4.0,0.3435392,0.0,0,0,0,
1627181291.605,,6000.0,12.68651,0.0632881,0.0,3,0.9973402,0.0,,,,,,,,,,,,,,32,1,4.0,0.3713303,0.0,0,0,0,
1627181381.076,,6000.0,13.69581,0.06327265,0.0,3,0.9972118,0.0,,,,,,,,,,,,,,32,1,4.0,0.3791199,0.0,0,0,0,
1627181467.457,,6000.0,14.71668,0.06321532,0.0,3,0.9972018,0.0,,,,,,,,,,,,,,32,1,4.0,0.3798208,0.0,0,0,0,
1627181557.117,,6000.0,15.70333,0.06317069,0.0,3,0.997293,0.0,,,,,,,,,,,,,,32,1,4.0,0.3970299,0.0,0,0,0,
1627181649.018,,6000.0,16.7141,0.06308374,0.0,3,0.9972268,0.0,,,,,,,,,,,,,,32,1,4.0,0.3719311,0.0,0,0,0,
1627181737.359,,6000.0,17.70034,0.06297585,0.0,3,0.9971755,0.0,,,,,,,,,,,,,,32,1,4.0,0.3948212,0.0,0,0,0,
1627181823.939,,6000.0,18.67093,0.06285285,0.0,3,0.9973236,0.0,,,,,,,,,,,,,,32,1,4.0,0.3349495,0.0,0,0,0,
1627181912.92,,6000.0,19.70601,0.06270198,0.0,3,0.9974449,0.0,,,,,,,,,,,,,,32,1,4.0,0.3846283,0.0,0,1,0,
1627182001.631,,6000.0,20.69637,0.06252617,0.0,3,0.9974517,0.0,,,,,,,,,,,,,,32,1,4.0,0.370491,0.0,0,1,0,
1627182090.731,,6000.0,21.70068,0.06231422,0.0,3,0.9973459,0.0,,,,,,,,,,,,,,32,1,4.0,0.3483105,0.0,0,1,0,
1627182179.982,,6000.0,22.70535,0.06205663,0.0,3,0.9974535,0.0,,,,,,,,,,,,,,32,1,4.0,0.4088097,0.0,0,1,0,
1627182272.562,,6000.0,23.69367,0.06178246,0.0,3,0.9975832,0.0,,,,,,,,,,,,,,32,1,4.0,0.3526402,0.0,0,1,0,
1627182366.992,,6000.0,24.71835,0.06146874,0.0,3,0.9973303,0.0,,,,,,,,,,,,,,32,1,4.0,0.3752594,0.0,0,1,0,
1627182452.763,,6000.0,25.66647,0.06114259,0.0,3,0.9973929,0.0,,,,,,,,,,,,,,32,1,4.0,0.3148098,0.0,0,1,0,
1627182545.533,,6000.0,26.68705,0.06076147,0.0,3,0.9972505,0.0,,,,,,,,,,,,,,32,1,4.0,0.3356304,0.0,0,1,0,
1627182636.504,,6000.0,27.69342,0.06035745,0.0,3,0.997183,0.0,,,,,,,,,,,,,,32,1,4.0,0.3842106,0.0,0,1,0,
1627182724.895,,6000.0,28.71096,0.05990906,0.0,3,0.9972891,0.0,,,,,,,,,,,,,,32,1,4.0,0.3906498,0.0,0,1,0,
1627182812.995,,6000.0,29.69388,0.0594422,0.0,3,0.9973173,0.0,,,,,,,,,,,,,,32,1,4.0,0.3434792,0.0,0,1,0,
1627182916.644,,6000.0,30.8408,0.05880927,0.0,3,0.997438,0.0,,,,,,,,,,,,,,32,1,4.0,0.3635597,0.0,0,1,0,
1627182990.807,,6000.0,31.69249,0.05832418,0.0,3,0.9972078,0.0,,,,,,,,,,,,,,32,1,4.0,0.3556309,0.0,0,1,0,
1627183079.497,,6000.0,32.7021,0.05757282,0.0,3,0.9951401,0.0,,,,,,,,,,,,,,32,1,4.0,0.3667488,0.0,0,1,0,
1627183166.258,,6000.0,33.70818,0.05596282,0.0,3,0.9965661,0.0,,,,,,,,,,,,,,32,1,4.0,0.3642578,0.0,0,0,0,
1627183289.735,,6000.0,35.05253,0.01765937,0.0,3,0.9958016,0.0,,,,,,,,,,,,,,32,1,4.0,0.3922997,0.0,0,0,0,
1627183362.878,,6000.0,35.84477,0.01593484,0.0,3,0.9937731,0.0,,,,,,,,,,,,,,32,1,4.0,0.4261284,0.0,0,0,0,
1627183437.84,,6000.0,36.71281,0.01459658,0.0,3,0.9961131,0.0,,,,,,,,,,,,,,32,1,4.0,0.3957977,0.0,0,0,0,
1627183521.241,,6000.0,37.71137,0.0132298,0.0,3,0.9963274,0.0,,,,,,,,,,,,,,32,1,4.0,0.4193001,0.0,0,0,0,
1627183609.452,,6000.0,38.66619,0.01208542,0.0,3,0.996084,0.0,,,,,,,,,,,,,,32,1,4.0,0.2969398,0.0,0,0,0,
1627183702.532,,6000.0,39.68985,0.01104677,0.0,3,0.9965414,0.0,,,,,,,,,,,,,,32,1,4.0,0.3566208,0.0,0,0,0,
1627183797.202,,6000.0,40.71066,0.01013743,0.0,3,0.996668,0.0,,,,,,,,,,,,,,32,1,4.0,0.3752098,0.0,0,0,0,
1627183884.753,,6000.0,41.70741,0.009400806,0.0,3,0.9966025,0.0,,,,,,,,,,,,,,32,1,4.0,0.3952904,0.0,0,0,0,
1627183971.793,,6000.0,42.67648,0.008759156,0.0,3,0.9967917,0.0,,,,,,,,,,,,,,32,1,4.0,0.348381,0.0,0,1,0,
1627184063.804,,6000.0,43.71082,0.008172332,0.0,3,0.9968293,0.0,,,,,,,,,,,,,,32,1,4.0,0.3647079,0.0,0,1,0,
1627184151.665,,6000.0,44.72284,0.00767376,0.0,3,0.9968877,0.0,,,,,,,,,,,,,,32,1,4.0,0.396019,0.0,0,1,0,
1627184274.692,,6000.0,46.07452,0.007089303,0.0,3,0.996684,0.0,,,,,,,,,,,,,,32,1,4.0,0.406292,0.0,0,1,0,
1627184345.744,,6000.0,46.91128,0.006792478,0.0,3,0.997072,0.0,,,,,,,,,,,,,,32,1,4.0,0.4226112,0.0,0,1,0,
1627184418.656,,6000.0,47.68639,0.006520987,0.0,3,0.9969981,0.0,,,,,,,,,,,,,,32,1,4.0,0.3583298,0.0,0,1,0,
1627184506.937,,6000.0,48.74564,0.006211936,0.0,3,0.9971829,0.0,,,,,,,,,,,,,,32,1,4.0,0.4537697,0.0,0,1,0,
1627184606.127,,6000.0,49.69105,0.005929369,0.0,3,0.9970983,0.0,,,,,,,,,,,,,,32,1,4.0,0.376049,0.0,0,1,0,
1627184699.757,,6000.0,50.75542,0.005667242,0.0,3,0.9970362,0.0,,,,,,,,,,,,,,32,1,4.0,0.3920479,0.0,0,1,0,
1627184781.608,,6000.0,51.67822,0.005443588,0.0,3,0.9967851,0.0,,,,,,,,,,,,,,32,1,4.0,0.3470421,0.0,0,1,0,
1627184869.819,,6000.0,52.71291,0.00522249,0.0,3,0.9971434,0.0,,,,,,,,,,,,,,32,1,4.0,0.2580414,0.0,0,1,0,
1627184962.209,,6000.0,53.68736,0.005013867,0.0,3,0.9971438,0.0,,,,,,,,,,,,,,32,1,4.0,0.3566322,0.0,0,1,0,
1627185053.15,,6000.0,54.70315,0.004820598,0.0,3,0.9970511,0.0,,,,,,,,,,,,,,32,1,4.0,0.394001,0.0,0,1,0,
1627185139.161,,6000.0,55.70721,0.004651824,0.0,3,0.9969259,0.0,,,,,,,,,,,,,,32,1,4.0,0.3521919,0.0,0,0,0,
1627185227.051,,6000.0,56.73853,0.004495089,0.0,3,0.9970949,0.0,,,,,,,,,,,,,,32,1,4.0,0.2327499,0.0,0,0,0,
1627185315.932,,6000.0,57.72646,0.004352553,0.0,3,0.9969072,0.0,,,,,,,,,,,,,,32,1,4.0,0.2982292,0.0,0,0,0,
1627185409.962,,6000.0,58.68413,0.004215999,0.0,3,0.9969916,0.0,,,,,,,,,,,,,,32,1,4.0,0.3646507,0.0,0,0,0,
1627185497.153,,6000.0,59.68493,0.004088006,0.0,3,0.996964,0.0,,,,,,,,,,,,,,32,1,4.0,0.3213882,0.0,0,0,0,
1627195592.781,,2000.0,9.99828,0.05754969,0.0,3,0.9974506,0.0,,,,,,,,,,,,,,32,1,4.0,0.001891136,0.0,0,1,0,
1627195740.446,,2000.0,11.18968,0.05755652,0.0,3,0.9974751,0.0,,,,,,,,,,,,,,32,1,4.0,0.3532801,0.0,0,0,0,
1627195835.626,,2000.0,12.2043,0.05758868,0.0,3,0.9976249,0.0,,,,,,,,,,,,,,32,1,4.0,0.3877506,0.0,0,0,0,
1627195920.997,,2000.0,13.19335,0.05750214,0.0,3,0.997455,0.0,,,,,,,,,,,,,,32,1,4.0,0.3769703,0.0,0,0,0,
1627196008.187,,2000.0,14.19204,0.0574656,0.0,3,0.9973003,0.0,,,,,,,,,,,,,,32,1,4.0,0.3773603,0.0,0,0,0,
1627196097.088,,2000.0,15.20127,0.05741706,0.0,3,0.9974538,0.0,,,,,,,,,,,,,,32,1,4.0,0.3994293,0.0,0,0,0,
1627196184.909,,2000.0,16.2046,0.05733551,0.0,3,0.9973589,0.0,,,,,,,,,,,,,,32,1,4.0,0.4081497,0.0,0,0,0,
1627196272.77,,2000.0,17.21362,0.05729581,0.0,3,0.997361,0.0,,,,,,,,,,,,,,32,1,4.0,0.3876801,0.0,0,0,0,
1627196361.11,,2000.0,18.20496,0.05712999,0.0,3,0.9974415,0.0,,,,,,,,,,,,,,32,1,4.0,0.3805103,0.0,0,0,0,
1627196445.561,,2000.0,19.18462,0.05698329,0.0,3,0.9974616,0.0,,,,,,,,,,,,,,32,1,4.0,0.3463497,0.0,0,0,0,
1627196536.712,,2000.0,20.20192,0.05681867,0.0,3,0.9972338,0.0,,,,,,,,,,,,,,32,1,4.0,0.3536797,0.0,0,1,0,
1627196623.283,,2000.0,21.198,0.0566159,0.0,3,0.9974728,0.0,,,,,,,,,,,,,,32,1,4.0,0.3599586,0.0,0,1,0,
1627196711.453,,2000.0,22.18685,0.05639357,0.0,3,0.9974549,0.0,,,,,,,,,,,,,,32,1,4.0,0.3615303,0.0,0,1,0,
1627196802.184,,2000.0,23.1857,0.05612888,0.0,3,0.9973788,0.0,,,,,,,,,,,,,,32,1,4.0,0.3432808,0.0,0,1,0,
1627196892.064,,2000.0,24.20733,0.05583581,0.0,3,0.9973404,0.0,,,,,,,,,,,,,,32,1,4.0,0.3897991,0.0,0,1,0,
1627196980.485,,2000.0,25.17395,0.05553491,0.0,3,0.9974048,0.0,,,,,,,,,,,,,,32,1,4.0,0.3397408,0.0,0,1,0,
1627197070.236,,2000.0,26.19046,0.05517551,0.0,3,0.9974463,0.0,,,,,,,,,,,,,,32,1,4.0,0.3540096,0.0,0,1,0,
1627197159.206,,2000.0,27.20083,0.05479665,0.0,3,0.9974004,0.0,,,,,,,,,,,,,,32,1,4.0,0.3753395,0.0,0,1,0,
1627197246.747,,2000.0,28.17679,0.05436715,0.0,3,0.997672,0.0,,,,,,,,,,,,,,32,1,4.0,0.3528996,0.0,0,1,0,
1627197337.238,,2000.0,29.20531,0.05391835,0.0,3,0.997368,0.0,,,,,,,,,,,,,,32,1,4.0,0.3742905,0.0,0,1,0,
1627197425.448,,2000.0,30.20545,0.05342117,0.0,3,0.9974507,0.0,,,,,,,,,,,,,,32,1,4.0,0.3583603,0.0,0,1,0,
1627197515.449,,2000.0,31.19296,0.05287917,0.0,3,0.9972363,0.0,,,,,,,,,,,,,,32,1,4.0,0.3659515,0.0,0,1,0,
1627197599.95,,2000.0,32.20304,0.05226816,0.0,3,0.9973553,0.0,,,,,,,,,,,,,,32,1,4.0,0.3554688,0.0,0,1,0,
1627197692.31,,2000.0,33.22384,0.04698368,0.0,3,0.9849886,0.0,,,,,,,,,,,,,,32,1,4.0,0.4372215,0.0,0,1,0,
1627197809.268,,2000.0,34.58221,0.009274239,0.0,3,0.9956239,0.0,,,,,,,,,,,,,,32,1,4.0,0.3061523,0.0,0,0,0,
1627197878.491,,2000.0,35.31532,0.008159011,0.0,3,0.9951754,0.0,,,,,,,,,,,,,,32,1,4.0,0.4349098,0.0,0,0,0,
1627197986.519,,2000.0,36.50625,0.006746619,0.0,3,0.9956483,0.0,,,,,,,,,,,,,,32,1,4.0,0.3532372,0.0,0,0,0,
1627198059.042,,2000.0,37.27325,0.00603254,0.0,3,0.9956689,0.0,,,,,,,,,,,,,,32,1,4.0,0.3956223,0.0,0,0,0,
1627198138.683,,2000.0,38.20628,0.005336947,0.0,3,0.9958913,0.0,,,,,,,,,,,,,,32,1,4.0,0.3779297,0.0,0,0,0,
1627198230.904,,2000.0,39.19842,0.004722629,0.0,3,0.9961677,0.0,,,,,,,,,,,,,,32,1,4.0,0.3726616,0.0,0,0,0,
1627198324.804,,2000.0,40.22929,0.004216664,0.0,3,0.9964896,0.0,,,,,,,,,,,,,,32,1,4.0,0.3749619,0.0,0,0,0,
1627198411.585,,2000.0,41.19829,0.00382742,0.0,3,0.9963785,0.0,,,,,,,,,,,,,,32,1,4.0,0.3779106,0.0,0,0,0,
1627198502.105,,2000.0,42.19788,0.003503686,0.0,3,0.996443,0.0,,,,,,,,,,,,,,32,1,4.0,0.3805771,0.0,0,0,0,
1627198589.986,,2000.0,43.21465,0.003226645,0.0,3,0.9964541,0.0,,,,,,,,,,,,,,32,1,4.0,0.3953323,0.0,0,1,0,
1627198675.457,,2000.0,44.19019,0.003006086,0.0,3,0.9966605,0.0,,,,,,,,,,,,,,32,1,4.0,0.3658981,0.0,0,1,0,
1627198801.354,,2000.0,45.62725,0.00273459,0.0,3,0.9966751,0.0,,,,,,,,,,,,,,32,1,4.0,0.3700714,0.0,0,1,0,
1627198872.076,,2000.0,46.40128,0.002614444,0.0,3,0.9967352,0.0,,,,,,,,,,,,,,32,1,4.0,0.4113693,0.0,0,1,0,
1627198947.638,,2000.0,47.20171,0.002499779,0.0,3,0.997068,0.0,,,,,,,,,,,,,,32,1,4.0,0.3797607,0.0,0,1,0,
1627199042.978,,2000.0,48.19078,0.002374195,0.0,3,0.9969311,0.0,,,,,,,,,,,,,,32,1,4.0,0.3509903,0.0,0,1,0,
1627199128.439,,2000.0,49.18944,0.002266902,0.0,3,0.996877,0.0,,,,,,,,,,,,,,32,1,4.0,0.3184624,0.0,0,1,0,
1627199220.72,,2000.0,50.21334,0.00216179,0.0,3,0.9969497,0.0,,,,,,,,,,,,,,32,1,4.0,0.3938904,0.0,0,1,0,
1627199310.7,,2000.0,51.23967,0.00206793,0.0,3,0.9971738,0.0,,,,,,,,,,,,,,32,1,4.0,0.3853607,0.0,0,1,0,
1627199394.971,,2000.0,52.20148,0.001986628,0.0,3,0.9970989,0.0,,,,,,,,,,,,,,32,1,4.0,0.3629608,0.0,0,1,0,
1627199486.072,,2000.0,53.18117,0.001910446,0.0,3,0.9970638,0.0,,,,,,,,,,,,,,32,1,4.0,0.3306084,0.0,0,1,0,
1627199575.772,,2000.0,54.20206,0.001837095,0.0,3,0.9972229,0.0,,,,,,,,,,,,,,32,1,4.0,0.3751488,0.0,0,1,0,
1627199666.933,,2000.0,55.1973,0.001773409,0.0,3,0.9972803,0.0,,,,,,,,,,,,,,32,1,4.0,0.350811,0.0,0,1,0,
1627199753.833,,2000.0,56.22641,0.001714609,0.0,3,0.9970807,0.0,,,,,,,,,,,,,,32,1,4.0,0.2757416,0.0,0,1,0,
1627199844.134,,2000.0,57.17673,0.001660377,0.0,3,0.997143,0.0,,,,,,,,,,,,,,32,1,4.0,0.3390198,0.0,0,0,0,
1627199974.59,,2000.0,58.58955,0.001586149,0.0,3,0.9970526,0.0,,,,,,,,,,,,,,32,1,4.0,0.3803406,0.0,0,0,0,
1627200043.783,,2000.0,59.40562,0.001550042,0.0,3,0.9968693,0.0,,,,,,,,,,,,,,32,1,4.0,0.3652916,0.0,0,0,0,
1627200255.421,,2000.0,60.01623,0.001523231,0.0,3,0.9974505,0.0,,,,,,,,,,,,,,32,1,4.0,0.0574379,0.0,0,0,0,
1627202905.582,,100.0,10.68449,0.007602297,0.0,3,0.9974124,0.0,,,,,,,,,,,,,,32,1,4.0,0.3607502,0.0,0,1,0,
1627202995.193,,100.0,11.68942,0.007601297,0.0,3,0.9973103,0.0,,,,,,,,,,,,,,32,1,4.0,0.3498907,0.0,0,1,0,
1627203093.102,,100.0,12.70019,0.007675052,0.0,3,0.9919418,0.0,,,,,,,,,,,,,,32,1,4.0,0.3774805,0.0,0,1,0,
1627203180.043,,100.0,13.70606,0.007593553,0.0,3,0.9975229,0.0,,,,,,,,,,,,,,32,1,4.0,0.37918,0.0,0,0,0,
1627203271.563,,100.0,14.70362,0.007587158,0.0,3,0.9974536,0.0,,,,,,,,,,,,,,32,1,4.0,0.3625498,0.0,0,0,0,
1627203359.094,,100.0,15.70193,0.007578963,0.0,3,0.9974224,0.0,,,,,,,,,,,,,,32,1,4.0,0.3986797,0.0,0,0,0,
1627203451.505,,100.0,16.71022,0.007567439,0.0,3,0.9974392,0.0,,,,,,,,,,,,,,32,1,4.0,0.4008503,0.0,0,0,0,
1627203539.815,,100.0,17.68312,0.007554377,0.0,3,0.997381,0.0,,,,,,,,,,,,,,32,1,4.0,0.3646202,0.0,0,0,0,
1627203630.526,,100.0,18.70298,0.007534328,0.0,3,0.9973192,0.0,,,,,,,,,,,,,,32,1,4.0,0.3959007,0.0,0,0,0,
1627203718.037,,100.0,19.71549,0.00751069,0.0,3,0.9973982,0.0,,,,,,,,,,,,,,32,1,4.0,0.3638802,0.0,0,0,0,
1627203808.647,,100.0,20.72623,0.007481489,0.0,3,0.9973795,0.0,,,,,,,,,,,,,,32,1,4.0,0.3791504,0.0,0,0,0,
1627203893.678,,100.0,21.67395,0.00750712,0.0,3,0.9909431,0.0,,,,,,,,,,,,,,32,1,4.0,0.33605,0.0,0,1,0,
1627203985.848,,100.0,22.67765,0.007412536,0.0,3,0.9975102,0.0,,,,,,,,,,,,,,32,1,4.0,0.3467312,0.0,0,1,0,
1627204078.109,,100.0,23.6727,0.00736875,0.0,3,0.9972424,0.0,,,,,,,,,,,,,,32,1,4.0,0.332489,0.0,0,1,0,
1627204167.559,,100.0,24.67659,0.007325124,0.0,3,0.9973977,0.0,,,,,,,,,,,,,,32,1,4.0,0.3438511,0.0,0,1,0,
1627204254.4,,100.0,25.68151,0.007276715,0.0,3,0.9975768,0.0,,,,,,,,,,,,,,32,1,4.0,0.3504715,0.0,0,1,0,
1627204376.547,,100.0,27.02155,0.007200386,0.0,3,0.9974181,0.0,,,,,,,,,,,,,,32,1,4.0,0.28442,0.0,0,1,0,
1627204442.39,,100.0,27.7417,0.007158777,0.0,3,0.9975048,0.0,,,,,,,,,,,,,,32,1,4.0,0.3465405,0.0,0,1,0,
1627204526.731,,100.0,28.69696,0.007098814,0.0,3,0.9973733,0.0,,,,,,,,,,,,,,32,1,4.0,0.3490505,0.0,0,1,0,
1627204616.122,,100.0,29.69776,0.007033233,0.0,3,0.9974169,0.0,,,,,,,,,,,,,,32,1,4.0,0.38377,0.0,0,1,0,
1627204718.001,,100.0,30.80109,0.006948177,0.0,3,0.9973574,0.0,,,,,,,,,,,,,,32,1,4.0,0.3705406,0.0,0,1,0,
1627204794.403,,100.0,31.68389,0.006873314,0.0,3,0.9973492,0.0,,,,,,,,,,,,,,32,1,4.0,0.3530197,0.0,0,1,0,
1627204884.374,,100.0,32.69334,0.006726478,0.0,3,0.9973532,0.0,,,,,,,,,,,,,,32,1,4.0,0.3372574,0.0,0,1,0,
1627205003.581,,100.0,34.06263,0.00103685,0.0,3,0.990005,0.0,,,,,,,,,,,,,,32,1,4.0,0.3611603,0.0,0,1,0,
1627205071.804,,100.0,34.80341,0.0007930778,0.0,3,0.9923592,0.0,,,,,,,,,,,,,,32,1,4.0,0.3884087,0.0,0,0,0,
1627205180.013,,100.0,36.03281,0.0005544495,0.0,3,0.9934919,0.0,,,,,,,,,,,,,,32,1,4.0,0.4137115,0.0,0,0,0,
1627205252.725,,100.0,36.81013,0.0004611244,0.0,3,0.9933207,0.0,,,,,,,,,,,,,,32,1,4.0,0.3955307,0.0,0,0,0,
1627205328.207,,100.0,37.70514,0.0003981904,0.0,3,0.993463,0.0,,,,,,,,,,,,,,32,1,4.0,0.3871078,0.0,0,0,0,
1627205421.837,,100.0,38.72678,0.0003376965,0.0,3,0.9957902,0.0,,,,,,,,,,,,,,32,1,4.0,0.4066391,0.0,0,0,0,
1627205507.738,,100.0,39.68863,0.0002999709,0.0,3,0.9959639,0.0,,,,,,,,,,,,,,32,1,4.0,0.3517685,0.0,0,0,0,
1627205628.026,,100.0,41.0496,0.0002640474,0.0,3,0.996427,0.0,,,,,,,,,,,,,,32,1,4.0,0.4780617,0.0,0,0,0,
1627205700.398,,100.0,41.84626,0.0002476147,0.0,3,0.9963878,0.0,,,,,,,,,,,,,,32,1,4.0,0.4161606,0.0,0,0,0,
1627205773.47,,100.0,42.70337,0.0002341536,0.0,3,0.996204,0.0,,,,,,,,,,,,,,32,1,4.0,0.3857994,0.0,0,0,0,
1627205863.711,,100.0,43.7014,0.0002217791,0.0,3,0.9959593,0.0,,,,,,,,,,,,,,32,1,4.0,0.3316803,0.0,0,1,0,
1627205950.622,,100.0,44.70634,0.0002113931,0.0,3,0.9960872,0.0,,,,,,,,,,,,,,32,1,4.0,0.3600388,0.0,0,1,0,
1627206042.812,,100.0,45.6851,0.00020407,0.0,3,0.9952723,0.0,,,,,,,,,,,,,,32,1,4.0,0.3600922,0.0,0,1,0,
1627206130.963,,100.0,46.67485,0.0001980565,0.0,3,0.9956173,0.0,,,,,,,,,,,,,,32,1,4.0,0.3466415,0.0,0,1,0,
1627206220.173,,100.0,47.67049,0.0001921287,0.0,3,0.9952185,0.0,,,,,,,,,,,,,,32,1,4.0,0.3331299,0.0,0,1,0,
1627206308.964,,100.0,48.69247,0.0001871875,0.0,3,0.9954258,0.0,,,,,,,,,,,,,,32,1,4.0,0.3405609,0.0,0,1,0,
1627206404.594,,100.0,49.69455,0.0001840141,0.0,3,0.9966459,0.0,,,,,,,,,,,,,,32,1,4.0,0.3510208,0.0,0,1,0,
1627206504.483,,100.0,50.93888,0.0001839602,0.0,3,0.9842702,0.0,,,,,,,,,,,,,,32,1,4.0,0.3552399,0.0,0,1,0,
1627206578.146,,100.0,51.66858,0.0001779891,0.0,3,0.9960655,0.0,,,,,,,,,,,,,,32,1,4.0,0.3277588,0.0,0,1,0,
1627206662.267,,100.0,52.72102,0.0001749988,0.0,3,0.9967456,0.0,,,,,,,,,,,,,,32,1,4.0,0.3295822,0.0,0,1,0,
1627206754.227,,100.0,53.68836,0.0001727193,0.0,3,0.9965508,0.0,,,,,,,,,,,,,,32,1,4.0,0.3464012,0.0,0,1,0,
1627206841.708,,100.0,54.66698,0.0001695142,0.0,3,0.9968855,0.0,,,,,,,,,,,,,,32,1,4.0,0.3300667,0.0,0,1,0,
1627206969.055,,100.0,56.08024,0.0002531326,0.0,3,0.7755925,0.0,,,,,,,,,,,,,,32,1,4.0,0.3763008,0.0,0,1,0,
1627207039.207,,100.0,56.89969,0.0001655416,0.0,3,0.9962398,0.0,,,,,,,,,,,,,,32,1,4.0,0.370182,0.0,0,1,0,
1627207107.27,,100.0,57.68002,0.0001630065,0.0,3,0.9969783,0.0,,,,,,,,,,,,,,32,1,4.0,0.3489876,0.0,0,0,0,
1627207198.0,,100.0,58.68288,0.0001606438,0.0,3,0.9963874,0.0,,,,,,,,,,,,,,32,1,4.0,0.3430519,0.0,0,0,0,
1627207287.021,,100.0,59.67261,0.0001582858,0.0,3,0.9952906,0.0,,,,,,,,,,,,,,32,1,4.0,0.3361015,0.0,0,0,0,
1627207474.611,,100.0,59.99625,0.000159396,0.0,3,0.9952859,0.0,,,,,,,,,,,,,,32,1,4.0,0.01247025,0.0,0,0,0,